[34m[1mAMP: [39m[22mrunning Automatic Mixed Precision (AMP) checks with YOLOv8n...
Downloading https://github.com/ultralytics/assets/releases/download/v0.0.0/yolov8n.pt to 'yolov8n.pt'...
100%|â–ˆâ–ˆâ–ˆâ–ˆâ–ˆâ–ˆâ–ˆâ–ˆâ–ˆâ–ˆâ–ˆâ–ˆâ–ˆâ–ˆâ–ˆâ–ˆâ–ˆâ–ˆâ–ˆâ–ˆâ–ˆâ–ˆâ–ˆâ–ˆâ–ˆâ–ˆâ–ˆâ–ˆâ–ˆâ–ˆâ–ˆâ–ˆâ–ˆâ–ˆâ–ˆâ–ˆâ–ˆâ–ˆâ–ˆâ–ˆâ–ˆâ–ˆâ–ˆâ–ˆâ–ˆâ–ˆâ–ˆâ–ˆâ–ˆâ–ˆâ–ˆâ–ˆâ–ˆâ–ˆâ–ˆâ–ˆâ–ˆâ–ˆâ–ˆâ–ˆâ–ˆâ–ˆâ–ˆâ–ˆâ–ˆâ–ˆâ–ˆâ–ˆâ–ˆâ–ˆâ–ˆâ–ˆâ–ˆâ–ˆâ–ˆâ–ˆâ–ˆâ–ˆâ–ˆ| 6.23M/6.23M [00:00<00:00, 201MB/s]
[34m[1mAMP: [39m[22mchecks passed âœ…
[34m[1mtrain: [39m[22mScanning /home/ubuntu/vision-matt/yolo-detections-matt/data/agrosuper/splitted-dataset/train/labels... 509 images
[34m[1mtrain: [39m[22mNew cache created: /home/ubuntu/vision-matt/yolo-detections-matt/data/agrosuper/splitted-dataset/train/labels.cache
[34m[1mval: [39m[22mScanning /home/ubuntu/vision-matt/yolo-detections-matt/data/agrosuper/splitted-dataset/valid/labels... 114 images,
[34m[1mval: [39m[22mNew cache created: /home/ubuntu/vision-matt/yolo-detections-matt/data/agrosuper/splitted-dataset/valid/labels.cache
Exception ignored in: <function _releaseLock at 0x7f0a847f7be0>
Traceback (most recent call last):
  File "/home/ubuntu/anaconda3/envs/vision-cap/lib/python3.10/logging/__init__.py", line 228, in _releaseLock
    def _releaseLock():
KeyboardInterrupt:
Plotting labels to runs/detect/splitted-dataset-yolov812/labels.jpg...
[34m[1moptimizer:[39m[22m AdamW(lr=0.001667, momentum=0.9) with parameter groups 77 weight(decay=0.0), 84 weight(decay=0.000375), 83 bias(decay=0.0)
Image sizes 640 train, 640 val
Using 8 dataloader workers
Logging results to [1mruns/detect/splitted-dataset-yolov812
Starting training for 120 epochs...
      Epoch    GPU_mem   box_loss   cls_loss   dfl_loss  Instances       Size
  0%|          | 0/11 [00:05<?, ?it/s]
Traceback (most recent call last):
  File "/home/ubuntu/anaconda3/envs/vision-cap/lib/python3.10/site-packages/torch/utils/data/dataloader.py", line 1132, in _try_get_data
    data = self._data_queue.get(timeout=timeout)
  File "/home/ubuntu/anaconda3/envs/vision-cap/lib/python3.10/queue.py", line 179, in get
    raise Empty
_queue.Empty
The above exception was the direct cause of the following exception:
Traceback (most recent call last):
  File "/home/ubuntu/vision-matt/yolo-detections-matt/main_v8.py", line 69, in <module>
    main(args)
  File "/home/ubuntu/vision-matt/yolo-detections-matt/main_v8.py", line 40, in main
    train_results = target_model.train(
  File "/home/ubuntu/anaconda3/envs/vision-cap/lib/python3.10/site-packages/ultralytics/engine/model.py", line 377, in train
    self.trainer.train()
  File "/home/ubuntu/anaconda3/envs/vision-cap/lib/python3.10/site-packages/ultralytics/engine/trainer.py", line 192, in train
    self._do_train(world_size)
  File "/home/ubuntu/anaconda3/envs/vision-cap/lib/python3.10/site-packages/ultralytics/engine/trainer.py", line 315, in _do_train
    for i, batch in pbar:
  File "/home/ubuntu/anaconda3/envs/vision-cap/lib/python3.10/site-packages/tqdm/std.py", line 1182, in __iter__
    for obj in iterable:
  File "/home/ubuntu/anaconda3/envs/vision-cap/lib/python3.10/site-packages/ultralytics/data/build.py", line 38, in __iter__
    yield next(self.iterator)
  File "/home/ubuntu/anaconda3/envs/vision-cap/lib/python3.10/site-packages/torch/utils/data/dataloader.py", line 633, in __next__
    data = self._next_data()
  File "/home/ubuntu/anaconda3/envs/vision-cap/lib/python3.10/site-packages/torch/utils/data/dataloader.py", line 1328, in _next_data
    idx, data = self._get_data()
  File "/home/ubuntu/anaconda3/envs/vision-cap/lib/python3.10/site-packages/torch/utils/data/dataloader.py", line 1284, in _get_data
    success, data = self._try_get_data()
  File "/home/ubuntu/anaconda3/envs/vision-cap/lib/python3.10/site-packages/torch/utils/data/dataloader.py", line 1145, in _try_get_data
    raise RuntimeError('DataLoader worker (pid(s) {}) exited unexpectedly'.format(pids_str)) from e
RuntimeError: DataLoader worker (pid(s) 10365, 10373, 10381, 10389, 10397, 10405, 10413, 10421) exited unexpectedly
Traceback (most recent call last):
  File "/home/ubuntu/anaconda3/envs/vision-cap/lib/python3.10/site-packages/torch/utils/data/dataloader.py", line 1132, in _try_get_data
    data = self._data_queue.get(timeout=timeout)
  File "/home/ubuntu/anaconda3/envs/vision-cap/lib/python3.10/queue.py", line 179, in get
    raise Empty
_queue.Empty
The above exception was the direct cause of the following exception:
Traceback (most recent call last):
  File "/home/ubuntu/vision-matt/yolo-detections-matt/main_v8.py", line 69, in <module>
    main(args)
  File "/home/ubuntu/vision-matt/yolo-detections-matt/main_v8.py", line 40, in main
    train_results = target_model.train(
  File "/home/ubuntu/anaconda3/envs/vision-cap/lib/python3.10/site-packages/ultralytics/engine/model.py", line 377, in train
    self.trainer.train()
  File "/home/ubuntu/anaconda3/envs/vision-cap/lib/python3.10/site-packages/ultralytics/engine/trainer.py", line 192, in train
    self._do_train(world_size)
  File "/home/ubuntu/anaconda3/envs/vision-cap/lib/python3.10/site-packages/ultralytics/engine/trainer.py", line 315, in _do_train
    for i, batch in pbar:
  File "/home/ubuntu/anaconda3/envs/vision-cap/lib/python3.10/site-packages/tqdm/std.py", line 1182, in __iter__
    for obj in iterable:
  File "/home/ubuntu/anaconda3/envs/vision-cap/lib/python3.10/site-packages/ultralytics/data/build.py", line 38, in __iter__
    yield next(self.iterator)
  File "/home/ubuntu/anaconda3/envs/vision-cap/lib/python3.10/site-packages/torch/utils/data/dataloader.py", line 633, in __next__
    data = self._next_data()
  File "/home/ubuntu/anaconda3/envs/vision-cap/lib/python3.10/site-packages/torch/utils/data/dataloader.py", line 1328, in _next_data
    idx, data = self._get_data()
  File "/home/ubuntu/anaconda3/envs/vision-cap/lib/python3.10/site-packages/torch/utils/data/dataloader.py", line 1284, in _get_data
    success, data = self._try_get_data()
  File "/home/ubuntu/anaconda3/envs/vision-cap/lib/python3.10/site-packages/torch/utils/data/dataloader.py", line 1145, in _try_get_data
    raise RuntimeError('DataLoader worker (pid(s) {}) exited unexpectedly'.format(pids_str)) from e
RuntimeError: DataLoader worker (pid(s) 10365, 10373, 10381, 10389, 10397, 10405, 10413, 10421) exited unexpectedly